
--
DEBUG     2024-06-21 12:08:18  Logging level set to DEBUG
DEBUG     2024-06-21 12:08:18  Created DB link: 'sqlite:///:memory:'
DEBUG     2024-06-21 12:08:18  Using backend: loky
DEBUG     2024-06-21 12:08:18  Executing 10 tasks on 2 workers (backend:loky)
DEBUG     2024-06-21 12:08:19  Encountered exception in task, propagating to main process
DEBUG     2024-06-21 12:08:19  Executed 4 of 10 tasks (40%) with return_as=generator_unordered
TestException at failfast.py:20::faulty_step "<unkown>": test error
ERROR     2024-08-09 08:38:57  exception calling callback for <Future at 0x10e1bda30 state=finished returned list>
Traceback (most recent call last):
  File "/Users/michele/dev/mltraq/.venv/lib/python3.9/site-packages/joblib/externals/loky/_base.py", line 26, in _invoke_callbacks
    callback(self)
  File "/Users/michele/dev/mltraq/.venv/lib/python3.9/site-packages/joblib/parallel.py", line 828, in __call__
    self._dispatch_new()
  File "/Users/michele/dev/mltraq/.venv/lib/python3.9/site-packages/joblib/parallel.py", line 843, in _dispatch_new
    self.parallel.dispatch_next()
  File "/Users/michele/dev/mltraq/.venv/lib/python3.9/site-packages/joblib/parallel.py", line 1429, in dispatch_next
    if not self.dispatch_one_batch(self._original_iterator):
  File "/Users/michele/dev/mltraq/.venv/lib/python3.9/site-packages/joblib/parallel.py", line 1517, in dispatch_one_batch
    self._dispatch(tasks)
  File "/Users/michele/dev/mltraq/.venv/lib/python3.9/site-packages/joblib/parallel.py", line 1418, in _dispatch
    job = self._backend.apply_async(batch, callback=batch_tracker)
  File "/Users/michele/dev/mltraq/.venv/lib/python3.9/site-packages/joblib/_parallel_backends.py", line 588, in apply_async
    future = self._workers.submit(func)
  File "/Users/michele/dev/mltraq/.venv/lib/python3.9/site-packages/joblib/externals/loky/reusable_executor.py", line 225, in submit
    return super().submit(fn, *args, **kwargs)
  File "/Users/michele/dev/mltraq/.venv/lib/python3.9/site-packages/joblib/externals/loky/process_executor.py", line 1235, in submit
    raise RuntimeError(
RuntimeError: cannot schedule new futures after interpreter shutdown
--


